<robot name="example_robot">
    <link name="link0_passive">
        <visual>
            <material name="black">
                <color rgba="0 0 0 1"/>
            </material>
            <geometry>
                <origin xyz="0 0 0" rpy="0 0 0"/>
                <cylinder length="0.0" radius="0.0"/>
            </geometry>
        </visual>
    </link>
   
    <joint name="q0_x" type="fixed">
        <origin xyz="0 0 0" rpy="0 1.571 0"/>
        <parent link="link0_passive"/>
        <child link="podstawa"/>
    </joint>
	
	<link name="podstawa">
        <visual>
			 <parent link="q0_x"/>
			<child link="link0_x_axis"/>
            <origin xyz="-1.3775 0 0" rpy="0 1.571 0"/>
            <material name="black"/>
            <geometry>
                <cylinder length="2.755" radius="0.3"/>
            </geometry>
        </visual>
    </link>
	
	 <link name="link0_x_axis">
        <visual>
			<parent link="podstawa"/>
			<child link="link1"/>
            <material name="gray">
                <color rgba="0.3 0.3 0.3 1"/>
            </material>
            <geometry>
                <origin xyz="0 0 0" rpy="0 0 0"/>
                <cylinder length="0" radius="0"/>
            </geometry>
        </visual>
    </link>
	
	
	
    <link name="link1"/>
	
	
    <link name="link1_x_axis">
        <visual>
            <origin xyz="0 0 0.25" rpy="0 0 0"/>
            <material name="gray"/>
            <geometry>
                <cylinder length="0" radius="0"/>
            </geometry>
        </visual>
    </link>

	

    <joint name="q1" type="revolute">
        <origin xyz="0 0 2.755" rpy="0 0 0"/>
        <parent link="link0_passive"/>
        <child link="link1"/>
        <axis xyz="0 0 1"/>
    </joint>

    

    <joint name="q1_passive" type="fixed">
        <origin xyz="0 0 0" rpy="1.57 0 0"/>
        <parent link="link1"/>
        <child link="link1_passive"/>
    </joint>
    <link name="link1_passive">
        <visual>
            <origin xyz="0 0 0.25" rpy="0 0 0"/>
            <material name="black"/>
            <geometry>
                <cylinder length="0" radius="0"/>
            </geometry>
        </visual>
    </link>
	
	
    <joint name="q1_x" type="fixed">
        <origin xyz="0 0 0" rpy="0 1.571 0"/>
        <parent link="link1_passive"/>
        <child link="z2"/>
    </joint>

		<link name="z2">
        <visual>
            <origin xyz="0 0 0" rpy="0 1.571 0"/>
            <material name="gray"/>
            <geometry>
                <cylinder length="0.65" radius="0.35"/>
            </geometry>
        </visual>
    </link>
    
    <joint name="q1_x" type="fixed">
        <origin xyz="0 0 0" rpy="0 1.571 0"/>
        <parent link="link1_passive"/>
        <child link="link2_x_axis"/>
    </joint>
	
		
	
	
	
    <link name="link2"/>
    <link name="link2_x_axis">
        <visual>
            <origin xyz="0 0 0.25" rpy="0 0 0"/>
            <material name="gray"/>
            <geometry>
                <cylinder length="0" radius="0"/>
            </geometry>
        </visual>
    </link>
	

	
    <joint name="q2" type="revolute">
        <origin xyz="0 0 0" rpy="0 0 1.57"/>
        <parent link="link1_passive"/>
        <child link="link2"/>
        <axis xyz="0 0 1"/>
    </joint>
   

    <joint name="q2_passive" type="fixed">
        <origin xyz="4.1 0 0" rpy="3.14 0 0"/>
        <parent link="link2"/>
        <child link="link2_passive"/>
    </joint>
	
	
	
    <link name="link2_passive">
        <visual>
            <origin xyz="-2.05 0 0" rpy="0 1.57 0"/>
            <material name="black"/>
            <geometry>
                <cylinder length="4.1" radius="0.3"/>
            </geometry>
        </visual>
    </link>
	

	
    <joint name="q2_x" type="fixed">
        <origin xyz="0 0 0" rpy="0 1.571 0"/>
        <parent link="link2_passive"/>
        <child link="z3"/>
    </joint>
	
		<link name="z3">
        <visual>
            <origin xyz="0.05 0 0" rpy="0 1.571 0"/>
            <material name="gray"/>
            <geometry>
                <cylinder length="0.75" radius="0.35"/>
            </geometry>
        </visual>
    </link>
	
    <link name="link3"/>
    <link name="link3_x_axis">
        <visual>
            <origin xyz="0 0 0.25" rpy="0 0 0"/>
            <material name="gray"/>
            <geometry>
                <cylinder length="0" radius="0"/>
            </geometry>
        </visual>
    </link>
    <joint name="q3" type="revolute">
        <origin xyz="0 0 -0.098" rpy="0 0 -1.57"/>
        <parent link="link2_passive"/>
        <child link="link3"/>
        <axis xyz="0 0 1"/>
    </joint>
    <joint name="q3_passive" type="fixed">
        <origin xyz="0 0 0" rpy="1.57 0 0"/>
        <parent link="link3"/>
        <child link="link3_passive"/>
    </joint>
    <link name="link3_passive">
        <visual>
            <origin xyz="0 0 -1.2" rpy="0 0 0"/>
            <material name="black"/>
            <geometry>
                <cylinder length="2.2" radius="0.3"/>
            </geometry>
        </visual>
    </link>
    <joint name="q3_x" type="fixed">
        <origin xyz="0 0 0" rpy="0 1.571 0"/>
        <parent link="link3_passive"/>
        <child link="link4_x_axis"/>
    </joint>
	
	
	
    <link name="link4"/>
    <link name="link4_x_axis">
        <visual>
            <origin xyz="0 0 0.25" rpy="0 0 0"/>
            <material name="gray"/>
            <geometry>
                <cylinder length="0" radius="0"/>
            </geometry>
        </visual>
    </link>
    <joint name="q4" type="revolute">
        <origin xyz="0 0 -2.5008" rpy="0 0 0"/>
        <parent link="link3_passive"/>
        <child link="link4"/>
        <axis xyz="0 0 1"/>
      <visual>
            <origin xyz="0 0 0" rpy="0 0 0"/>
            <geometry>
                <box size="0.03 0.01 0.06"/>
            </geometry>
             <material name="Grey1">
                <color rgba="0.9 0.9 0.9 1.0"/>
            </material>
       </visual>
    </joint>
    <joint name="q4_passive" type="fixed">
        <origin xyz="0 0 0" rpy="1.05 0 0"/>
        <parent link="link4"/>
        <child link="link4_passive"/>
    </joint>
    <link name="link4_passive">
        <visual>
            <origin xyz="0 0 -0.5" rpy="0 0 0"/>
            <material name="black"/>
            <geometry>
                <cylinder length="1" radius="0.3"/>
            </geometry>
        </visual>
    </link>
    <joint name="q4_x" type="fixed">
        <origin xyz="0 0 0" rpy="0 0 1.571"/>
        <parent link="link4_passive"/>
        <child link="z4"/>
    </joint>
	
	<link name="z4">
        <visual>
            <origin xyz="0 0 0.1" rpy="0 0 1.571"/>
            <material name="gray"/>
            <geometry>
                <cylinder length="0.8" radius="0.35"/>
            </geometry>
        </visual>
    </link>
	
    <link name="link5"/>
    <link name="link5_x_axis">
        <visual>
            <origin xyz="0 0 0.25" rpy="0 0 0"/>
            <material name="gray"/>
            <geometry>
                <cylinder length="0" radius="0"/>
            </geometry>
        </visual>
    </link>
    <joint name="q5" type="revolute">
        <origin xyz="0 0 -1.1688" rpy="0 0 3.14"/>
        <parent link="link4_passive"/>
        <child link="link5"/>
        <axis xyz="0 0 1"/>
    </joint>
    <joint name="q5_passive" type="fixed">
        <origin xyz="0 0 0" rpy="1.571 0 0"/>
        <parent link="link5"/>
        <child link="link5_passive"/>
    </joint>
    <link name="link5_passive">
        <visual>
            <origin xyz="0 0 -0.9" rpy="0 0 0"/>
            <material name="black"/>
            <geometry>
                <cylinder length="1.8" radius="0.3"/>
            </geometry>
        </visual>
    </link>
    <joint name="q5_x" type="fixed">
        <origin xyz="0 0 0" rpy="0 1.571 0"/>
        <parent link="link5_passive"/>
        <child link="z5"/>
    </joint>
	
	<link name="z5">
        <visual>
            <origin xyz="0 0 0" rpy="1.571 0 0"/>
            <material name="gray"/>
            <geometry>
                <cylinder length="0.8" radius="0.35"/>
            </geometry>
        </visual>
    </link>
	
    <link name="link6"/>
    <link name="link6_x_axis">
        <visual>
            <origin xyz="0 0 0.25" rpy="0 0 0"/>
            <material name="gray"/>
            <geometry>
                <cylinder length="0" radius="0"/>
            </geometry>
        </visual>
    </link>
    <joint name="q6" type="revolute">
        <origin xyz="0 0 -2.027816549" rpy="0 0 -1.57"/>
        <parent link="link5_passive"/>
        <child link="link6"/>
        <axis xyz="0 0 1"/>
    </joint>
    <joint name="q6_passive" type="fixed">
        <origin xyz="0 0 0" rpy="3.14 0 0"/>
        <parent link="link6"/>
        <child link="link6_passive"/>
    </joint>
    <link name="link6_passive">
        <visual>
            <origin xyz="0 0 0.25" rpy="0 0 0"/>
            <material name="black"/>
            <geometry>
                <cylinder length="1" radius="0.3"/>
            </geometry>
        </visual>
    </link>
    <joint name="q6_x" type="fixed">
        <origin xyz="0 0 0" rpy="0 1.571 0"/>
        <parent link="link6_passive"/>
        <child link="chwytak"/>
    </joint>    
	
	<link name="chwytak">
        <visual>
            <origin xyz="-0.2 0 0" rpy="0 1.571 0"/>
            <material name="gray"/>
            <geometry>
                <cylinder length="0.4" radius="0.35"/>
            </geometry>
        </visual>
		<visual>
            <origin xyz="-0.65 0 0" rpy="1.571 0 0"/>
            <material name="gray"/>
            <geometry>
                <cylinder length="0.9" radius="0.15"/>
            </geometry>
        </visual>
		
		<visual>
            <origin xyz="-0.65 0 -0.20" rpy="0 0 1.571"/>
            <material name="gray"/>
            <geometry>
                <cylinder length="0.45" radius="0.15"/>
            </geometry>
        </visual>
		
		<visual>
            <origin xyz="-0.95 0 -0.45" rpy="0 1.571 0"/>
            <material name="gray"/>
            <geometry>
                <cylinder length="0.9" radius="0.15"/>
            </geometry>
        </visual>
		
		<visual>
            <origin xyz="-0.95 0.45 0" rpy="0 1.571 0"/>
            <material name="gray"/>
            <geometry>
                <cylinder length="0.9" radius="0.15"/>
            </geometry>
        </visual>
		<visual>
            <origin xyz="-0.95 -0.45 0" rpy="0 1.571 0"/>
            <material name="gray"/>
            <geometry>
                <cylinder length="0.9" radius="0.15"/>
            </geometry>
        </visual>
    </link>
	
	
	
</robot>
